<?xml version="1.0" ?>
<!-- =================================================================================== -->
<!-- |    This document was autogenerated by xacro from caster.urdf.xacro              | -->
<!-- |    EDITING THIS FILE BY HAND IS NOT RECOMMENDED                                 | -->
<!-- =================================================================================== -->
<robot name="caster_robot">
  <!-- Define material colors -->
  <material name="red">
    <color rgba="0.8 0 0 0.8"/>
  </material>
  <material name="purple">
    <color rgba="0.7 0 0.8 0.8"/>
  </material>
  <material name="black">
    <color rgba="0 0 0 0.75"/>
  </material>
  <material name="blue">
    <color rgba="0.0 0.0 0.8 0.8"/>
  </material>
  <material name="grey">
    <color rgba="0.5 0.5 0.5 0.8"/>
  </material>
  <!-- Gazebo diff drive plugin -->
  <gazebo>
    <plugin filename="libgazebo_ros_diff_drive.so" name="differential_drive_controller">
      <!-- Plugin update rate in Hz 
          An RPLIDAR A1 typically updates at 5.5-10 Hz -->
      <updateRate>50</updateRate>
      <!-- Name of left joint, defaults to `left_joint` -->
      <leftJoint>base_to_left_wheel</leftJoint>
      <!-- Name of right joint, defaults to `right_joint` -->
      <rightJoint>base_to_right_wheel</rightJoint>
      <!-- The distance from the center of one wheel to the other, in meters, defaults to 0.34 m -->
      <wheelSeparation>0.2</wheelSeparation>
      <!-- Diameter of the wheels, in meters, defaults to 0.15 m -->
      <wheelDiameter>0.06</wheelDiameter>
      <!-- Wheel acceleration, in rad/s^2, defaults to 0.0 rad/s^2 -->
      <wheelAcceleration>1.0</wheelAcceleration>
      <!-- Maximum torque which the wheels can produce, in Nm, defaults to 5 Nm -->
      <wheelTorque>20</wheelTorque>
      <!-- Topic to receive geometry_msgs/Twist message commands, defaults to `cmd_vel` -->
      <commandTopic>cmd_vel</commandTopic>
      <!-- Topic to publish nav_msgs/Odometry messages, defaults to `odom` -->
      <odometryTopic>odom</odometryTopic>
      <!-- Odometry frame, defaults to `odom` -->
      <odometryFrame>odom</odometryFrame>
      <!-- Robot frame to calculate odometry from, defaults to `base_footprint` -->
      <robotBaseFrame>base_footprint</robotBaseFrame>
      <!-- Odometry source, 0 for ENCODER, 1 for WORLD, defaults to WORLD -->
      <odometrySource>1</odometrySource>
      <!-- Set to true to publish transforms for the wheel links, defaults to false -->
      <publishWheelTF>true</publishWheelTF>
      <!-- Set to true to publish transforms for the odometry, defaults to true -->
      <publishOdom>true</publishOdom>
      <!-- Set to true to publish sensor_msgs/JointState on /joint_states for the wheel joints, defaults to false -->
      <publishWheelJointState>true</publishWheelJointState>
      <!-- Set to true to swap right and left wheels, defaults to true -->
      <legacyMode>false</legacyMode>
      <!-- Other plugin parameters -->
      <rosDebugLevel>info</rosDebugLevel>
      <publishOdomTF>true</publishOdomTF>
      <publishTf>1</publishTf>
    </plugin>
  </gazebo>
  <joint name="laser_joint" type="fixed">
    <axis xyz="0 1 0"/>
    <origin rpy="0 0 0" xyz="0 0 0.0635"/>
    <parent link="base_link"/>
    <child link="lidar_link"/>
  </joint>
  <!-- Hokuyo Laser -->
  <link name="lidar_link">
    <collision>
      <origin rpy="0 0 0" xyz="0 0 0"/>
      <geometry>
        <mesh filename="package://robot_description/meshes/rplidar.dae" scale="1 1 1"/>
      </geometry>
    </collision>
    <visual>
      <origin rpy="0 0 0" xyz="0 0 0"/>
      <geometry>
        <mesh filename="package://robot_description/meshes/rplidar.dae" scale="1 1 1"/>
      </geometry>
    </visual>
    <inertial>
      <mass value="1e-5"/>
      <origin rpy="0 0 0" xyz="0 0 0"/>
      <inertia ixx="1e-6" ixy="0" ixz="0" iyy="1e-6" iyz="0" izz="1e-6"/>
    </inertial>
  </link>
  <!-- GPU laser Plugin -->
  <gazebo reference="hokuyo_link">
    <sensor name="rplidar_sensor" type="gpu_ray">
      <pose>0 0 0 0 0 0</pose>
      <visualize>true</visualize>
      <update_rate>30</update_rate>
      <ray>
        <scan>
          <horizontal>
            <samples>720</samples>
            <resolution>1</resolution>
            <min_angle>-1.570796</min_angle>
            <max_angle>1.570796</max_angle>
          </horizontal>
        </scan>
        <range>
          <min>0.10</min>
          <max>30.0</max>
          <resolution>0.01</resolution>
        </range>
        <noise>
          <type>gaussian</type>
          <!-- Noise parameters based on published spec for Hokuyo laser
               achieving "+-30mm" accuracy at range < 10m.  A mean of 0.0m and
               stddev of 0.01m will put 99.7% of samples within 0.03m of the true
               reading. -->
          <mean>0.0</mean>
          <stddev>0.01</stddev>
        </noise>
      </ray>
      <plugin filename="libgazebo_ros_gpu_laser.so" name="gazebo_ros_head_hokuyo_controller">
        <topicName>/rrbot/laser/scan</topicName>
        <frameName>hokuyo_link</frameName>
      </plugin>
    </sensor>
  </gazebo>
  <!-- <xacro:include filename="kinect.urdf.xacro"/> -->
  <link name="base_footprint"/>
  <!-- Dummy link for the robot's base -->
  <link name="base_link">
    <visual name="base_visual">
      <origin rpy="0.0 0.0 0.0" xyz="0.0 0.0 0.0"/>
      <geometry>
        <box size="0.3 0.2 0.05"/>
      </geometry>
      <material name="black"/>
    </visual>
    <collision>
      <origin rpy="0.0 0.0 0.0" xyz="0.0 0.0 0.0"/>
      <geometry>
        <box size="0.3 0.2 0.05"/>
      </geometry>
    </collision>
    <inertial>
      <origin rpy="0 0 0" xyz="0 0 0"/>
      <mass value="1.0"/>
      <inertia ixx="0.0035416666666666674" ixy="0" ixz="0" iyy="0.0077083333333333335" iyz="0" izz="0.010833333333333334"/>
    </inertial>
  </link>
  <joint name="base_joint" type="fixed">
    <origin rpy="0.0 0.0 0.0" xyz="0.0 0.0 0.040"/>
    <parent link="base_footprint"/>
    <child link="base_link"/>
    <axis xyz="0.0 0.0 0.0"/>
  </joint>
  <!-- Right Wheel link& joint-->
  <link name="rear_right_wheel">
    <visual name="right_wheel_visual">
      <origin rpy="0.0 0.0 0.0" xyz="0.0 0.0 0.0"/>
      <geometry>
        <cylinder length="0.015" radius="0.03"/>
      </geometry>
      <material name="purple"/>
    </visual>
    <collision>
      <origin rpy="0.0 0.0 0.0" xyz="0.0 0.0 0.0"/>
      <geometry>
        <cylinder length="0.015" radius="0.03"/>
      </geometry>
    </collision>
    <inertial>
      <origin rpy="0 0 0" xyz="0 0 0"/>
      <mass value="0.5"/>
      <inertia ixx="0.00012187499999999998" ixy="0" ixz="0" iyy="0.00012187499999999998" iyz="0" izz="0.000225"/>
    </inertial>
  </link>
  <joint name="base_to_right_wheel" type="continuous">
    <origin rpy="1.5707963267948966 0 0" xyz="0.12 0.1077 -0.015"/>
    <parent link="base_link"/>
    <child link="rear_right_wheel"/>
    <axis xyz="0.0 0.0 1.0"/>
  </joint>
  <!-- Left Wheel link& joint-->
  <link name="rear_left_wheel">
    <visual name="left_wheel_visual">
      <origin rpy="0.0 0.0 0.0" xyz="0.0 0.0 0.0"/>
      <geometry>
        <cylinder length="0.015" radius="0.03"/>
      </geometry>
      <material name="purple"/>
    </visual>
    <collision>
      <origin rpy="0.0 0.0 0.0" xyz="0.0 0.0 0.0"/>
      <geometry>
        <cylinder length="0.015" radius="0.03"/>
      </geometry>
    </collision>
    <inertial>
      <origin rpy="0 0 0" xyz="0 0 0"/>
      <mass value="0.5"/>
      <inertia ixx="0.00012187499999999998" ixy="0" ixz="0" iyy="0.00012187499999999998" iyz="0" izz="0.000225"/>
    </inertial>
  </link>
  <joint name="base_to_left_wheel" type="continuous">
    <origin rpy="1.5707963267948966 0 0" xyz="0.12 -0.1077 -0.015"/>
    <parent link="base_link"/>
    <child link="rear_left_wheel"/>
    <axis xyz="0.0 0.0 1.0"/>
  </joint>
  <!-- Front Middle Caster Wheel link& joint-->
  <link name="caster_wheel">
    <visual name="caster_wheel_visual">
      <origin rpy="0.0 0.0 0.0" xyz="0.0 0.0 0.0"/>
      <geometry>
        <sphere radius="0.03"/>
      </geometry>
      <material name="purple"/>
    </visual>
    <collision>
      <origin rpy="0.0 0.0 0.0" xyz="0.0 0.0 0.0"/>
      <geometry>
        <sphere radius="0.03"/>
      </geometry>
    </collision>
    <inertial>
      <origin rpy="0 0 0" xyz="0 0 0"/>
      <mass value="0.5"/>
      <inertia ixx="0.00017999999999999998" ixy="0" ixz="0" iyy="0.00017999999999999998" iyz="0" izz="0.00017999999999999998"/>
    </inertial>
  </link>
  <joint name="base_to_caster_wheel" type="continuous">
    <origin rpy="0 0 0" xyz="-0.12 0.0 -0.015"/>
    <parent link="base_link"/>
    <child link="caster_wheel"/>
    <axis xyz="0.0 1.0 0.0"/>
  </joint>
</robot>

