<?xml version="1.0"?>
<robot xmlns:xacro="http://www.ros.org/wiki/xacro" name="caster_robot">

<xacro:include filename="material.xacro"/>
<xacro:include filename="inertial_calc.xacro"/>
<xacro:include filename="differential_drive_gazebo_plugin.urdf.xacro"/>
<xacro:include filename="laser.urdf.xacro"/>
<!-- <xacro:include filename="kinect.urdf.xacro"/> -->

<xacro:property name="radius" value="0.03"/>


<link name="base_footprint"/>   <!-- Dummy link for the robot's base -->

<link name="base_link">
    <visual name="base_visual">
        <origin xyz="0.0 0.0 0.0" rpy="0.0 0.0 0.0"/>
        <geometry>
            <box size="0.3 0.2 0.05"/>
        </geometry>
        <material name="black"/>
    </visual>

    <collision>
        <origin xyz="0.0 0.0 0.0" rpy="0.0 0.0 0.0"/>
        <geometry>
            <box size="0.3 0.2 0.05"/>
        </geometry>
    </collision>

    <xacro:box_inertial mass="1.0" x="0.3" y="0.2" z="0.05">
        <origin xyz="0 0 0" rpy="0 0 0"/>
    </xacro:box_inertial>
</link>

<joint name="base_joint" type="fixed">
    <origin xyz="0.0 0.0 0.040" rpy="0.0 0.0 0.0"/>
    <parent link="base_footprint"/>
    <child link="base_link"/>
    <axis xyz="0.0 0.0 0.0"/>
</joint>

<!-- Right Wheel link& joint-->
<link name="rear_right_wheel">
    <visual name="right_wheel_visual">
        <origin xyz="0.0 0.0 0.0" rpy="0.0 0.0 0.0"/>
        <geometry>
            <cylinder radius="${radius}" length="0.015"/>
        </geometry>
        <material name="purple"/>
    </visual>

    <collision>
        <origin xyz="0.0 0.0 0.0" rpy="0.0 0.0 0.0"/>
        <geometry>
            <cylinder radius="${radius}" length="0.015"/>
        </geometry>
    </collision>

    <xacro:cylinder_inertial mass="0.5" radius="${radius}" length="0.015">
        <origin xyz="0 0 0" rpy="0 0 0"/>
    </xacro:cylinder_inertial>
</link>
<joint name="base_to_right_wheel" type="continuous">
    <origin xyz="0.12 0.1077 -0.015" rpy="${pi/2} 0 0"/>
    <parent link="base_link"/>
    <child link="rear_right_wheel"/>
    <axis xyz="0.0 0.0 1.0"/>
</joint>

<!-- Left Wheel link& joint-->
<link name="rear_left_wheel">
    <visual name="left_wheel_visual">
        <origin xyz="0.0 0.0 0.0" rpy="0.0 0.0 0.0"/>
        <geometry>
            <cylinder radius="${radius}" length="0.015"/>
        </geometry>
        <material name="purple"/>
    </visual>

    <collision>
        <origin xyz="0.0 0.0 0.0" rpy="0.0 0.0 0.0"/>
        <geometry>
            <cylinder radius="${radius}" length="0.015"/>
        </geometry>
    </collision>

    <xacro:cylinder_inertial mass="0.5" radius="${radius}" length="0.015">
        <origin xyz="0 0 0" rpy="0 0 0"/>
    </xacro:cylinder_inertial>
</link>
<joint name="base_to_left_wheel" type="continuous">
    <origin xyz="0.12 -0.1077 -0.015" rpy="${pi/2} 0 0"/>
    <parent link="base_link"/>
    <child link="rear_left_wheel"/>
    <axis xyz="0.0 0.0 1.0"/>
</joint>

<!-- Front Middle Caster Wheel link& joint-->
<link name="caster_wheel">
    <visual name="caster_wheel_visual">
        <origin xyz="0.0 0.0 0.0" rpy="0.0 0.0 0.0"/>
        <geometry>
            <sphere radius="${radius}"/>
        </geometry>
        <material name="purple"/>
    </visual>

    <collision>
        <origin xyz="0.0 0.0 0.0" rpy="0.0 0.0 0.0"/>
        <geometry>
            <sphere radius="${radius}"/>
        </geometry>
    </collision>

    <xacro:sphere_inertial mass="0.5" radius="${radius}">
        <origin xyz="0 0 0" rpy="0 0 0"/>
    </xacro:sphere_inertial>
</link>
<joint name="base_to_caster_wheel" type="continuous">
    <origin xyz="-0.12 0.0 -0.015" rpy="0 0 0"/>
    <parent link="base_link"/>
    <child link="caster_wheel"/>
    <axis xyz="0.0 1.0 0.0"/>
</joint>

</robot>