<?xml version="1.0" ?>
<!-- =================================================================================== -->
<!-- |    This document was autogenerated by xacro from differential_drive_robot.xacro | -->
<!-- |    EDITING THIS FILE BY HAND IS NOT RECOMMENDED                                 | -->
<!-- =================================================================================== -->
<robot name="robot">
  <gazebo>
    <plugin filename="libgazebo_ros_diff_drive.so" name="differential_drive_controller">
      <legacyMode>false</legacyMode>
      <alwaysOn>true</alwaysOn>
      <updateRate>20</updateRate>
      <leftJoint>left_wheel_hinge</leftJoint>
      <rightJoint>right_wheel_hinge</rightJoint>
      <wheelSeparation>0.4</wheelSeparation>
      <wheelDiameter>0.1</wheelDiameter>
      <torque>20</torque>
      <commandTopic>cmd_vel</commandTopic>
      <odometryTopic>odom</odometryTopic>
      <odometryFrame>odom</odometryFrame>
      <robotBaseFrame>chassis</robotBaseFrame>
    </plugin>
  </gazebo>
  <gazebo reference="chassis">
    <material>Gazebo/Blue</material>
  </gazebo>
  <gazebo reference="right_wheel">
    <material>Gazebo/Black</material>
  </gazebo>
  <gazebo reference="left_wheel">
    <material>Gazebo/Black</material>
  </gazebo>
  <material name="black">
    <color rgba="0.0 0.0 0.0 1.0"/>
  </material>
  <material name="blue">
    <color rgba="0.0 0.0 0.8 1.0"/>
  </material>
  <material name="green">
    <color rgba="0.0 0.8 0.0 1.0"/>
  </material>
  <material name="grey">
    <color rgba="0.2 0.2 0.2 1.0"/>
  </material>
  <material name="orange">
    <color rgba="1.0 0.4235294117647059 0.0392156862745098 1.0"/>
  </material>
  <material name="brown">
    <color rgba="0.8705882352941177 0.8117647058823529 0.7647058823529411 1.0"/>
  </material>
  <material name="red">
    <color rgba="0.8 0.0 0.0 1.0"/>
  </material>
  <material name="white">
    <color rgba="1.0 1.0 1.0 1.0"/>
  </material>
  <!--Xacro variable declaration-->
  <!--Dimentions-->
  <!--Joint variables-->
  <!--Links Declaration-->
  <link name="chassis">
    <pose>0 0 0.1 0 0 0</pose>
    <inertial>
      <mass value="10.0"/>
      <origin rpy=" 0 0 0" xyz="0.0 0 0.1"/>
      <cylinder_inertia h="0.05" m="10" r="0.2"/>
      <inertia ixx="0.5" ixy="0" ixz="0" iyy="1.0" iyz="0" izz="0.1"/>
    </inertial>
    <collision name="collision">
      <geometry>
        <cylinder length="0.05" radius="0.2"/>
      </geometry>
    </collision>
    <visual name="chassis_visual">
      <origin rpy=" 0 0 0" xyz="0 0 0"/>
      <geometry>
        <cylinder length="0.05" radius="0.2"/>
      </geometry>
      <material name="blue"/>
    </visual>
    <collision name="caster_collision">
      <origin rpy=" 0 0 0" xyz="-0.15 0 -0.05"/>
      <geometry>
        <sphere radius="0.05"/>
      </geometry>
      <surface>
        <friction>
          <ode>
            <mu>0</mu>
            <mu2>0</mu2>
            <slip1>1.0</slip1>
            <slip2>1.0</slip2>
          </ode>
        </friction>
      </surface>
    </collision>
    <visual name="caster_visual">
      <origin rpy=" 0 0 0" xyz="-0.15 0 -0.05"/>
      <geometry>
        <sphere radius="0.05"/>
      </geometry>
      <material name="orange"/>
    </visual>
    <collision name="caster_collision2">
      <origin rpy=" 0 0 0" xyz="0.15 0 -0.05"/>
      <geometry>
        <sphere radius="0.05"/>
      </geometry>
      <surface>
        <friction>
          <ode>
            <mu>0</mu>
            <mu2>0</mu2>
            <slip1>1.0</slip1>
            <slip2>1.0</slip2>
          </ode>
        </friction>
      </surface>
    </collision>
    <visual name="caster2_visual">
      <origin rpy=" 0 0 0" xyz="0.15 0 -0.05"/>
      <geometry>
        <sphere radius="0.05"/>
      </geometry>
      <material name="orange"/>
    </visual>
  </link>
  <link name="left_wheel">
    <!--origin xyz="0.1 0.13 0.1" rpy="0 1.5707 1.5707"/-->
    <collision name="collision">
      <origin rpy="0 1.5707 1.5707" xyz="0 0 0"/>
      <geometry>
        <cylinder length="0.05" radius="0.1"/>
      </geometry>
    </collision>
    <visual name="left_wheel_visual">
      <origin rpy="0 1.5707 1.5707" xyz="0 0 0"/>
      <geometry>
        <cylinder length="0.05" radius="0.1"/>
      </geometry>
      <material name="black"/>
    </visual>
    <inertial>
      <origin rpy="0 1.5707 1.5707" xyz="0 0 0"/>
      <mass value="5"/>
      <cylinder_inertia h="0.05" m="5" r="0.1"/>
      <inertia ixx="1.0" ixy="0.0" ixz="0.0" iyy="1.0" iyz="0.0" izz="1.0"/>
    </inertial>
  </link>
  <link name="right_wheel">
    <collision name="collision">
      <origin rpy="0 1.5707 1.5707" xyz="0 0 0"/>
      <geometry>
        <cylinder length="0.05" radius="0.1"/>
      </geometry>
    </collision>
    <visual name="right_wheel_visual">
      <origin rpy="0 1.5707 1.5707" xyz="0 0 0"/>
      <geometry>
        <cylinder length="0.05" radius="0.1"/>
      </geometry>
      <material name="black"/>
    </visual>
    <inertial>
      <origin rpy="0 1.5707 1.5707" xyz="0 0 0"/>
      <mass value="5"/>
      <cylinder_inertia h="0.05" m="5" r="0.1"/>
      <inertia ixx="1.0" ixy="0.0" ixz="0.0" iyy="1.0" iyz="0.0" izz="1.0"/>
    </inertial>
  </link>
  <!--Joint Declaration-->
  <joint name="left_wheel_hinge" type="continuous">
    <origin rpy="0 0 0" xyz="0 -0.2 0"/>
    <child link="left_wheel"/>
    <parent link="chassis"/>
    <axis rpy="0 0 0" xyz="0 1 0"/>
    <limit effort="100" velocity="100"/>
    <joint_properties damping="0.0" friction="0.0"/>
  </joint>
  <joint name="right_wheel_hinge" type="continuous">
    <origin rpy="0 0 0" xyz="0.0 0.2 0"/>
    <child link="right_wheel"/>
    <parent link="chassis"/>
    <axis rpy="0 0 0" xyz="0 1 0"/>
    <limit effort="100" velocity="100"/>
    <joint_properties damping="0.0" friction="0.0"/>
  </joint>
</robot>

